Workbook

Sheet Settings
B1: Generator Data | M1: For Testing
B2: Voltage (kV, line-to-line) | G2: 11
B3: Power (MVA) | G3: 15.829
B4: PT Ratio | G4: 167
B5: CT Ratio | G5: 3600
B6: Xd (pu) | G6: 118
B7: X'd (pu) | G7: 20
B8: ZB (ohms secondary) | G8: =(G2^2/G3)*G5/G4 -> 164.78509
B10: Settings
B11: VNOM (volts secondary)
B12: INOM (amps secondary)
B13: Zone 1
B14: Z1 Diameter (ohms secondary) | G14: 114.7
B15: Z1 Offset (ohms secondary) | G15: -12.6
B16: Z1 Trip time (sec) | G16: 0.5
B17: Zone 2
B18: Z2 Diameter (ohms secondary) | G18: 149.1
B19: Z2 Offset (ohms secondary) | G19: -12.6
B20: Z2 Trip time (sec) | G20: 3
B23: Omicron Settings Zone 1
B24: |Z| (ohms) | G24: =(G14/2)+ABS(G15) -> 69.95
B25: Phi (degrees) | G25: =IF(G15<0,270,"IDK") -> 270
B26: Radius (Ohms) | G26: =G14/2 -> 57.35
B27: Start Angle (degrees) | G27: 360
B28: End angle (degrees) | G28: 0
B30: Omicron Settings Zone 2
B31: |Z| (ohms) | G31: =(G18/2)+ABS(G19) -> 87.15
B32: Phi (degrees) | G32: =IF(G19<0,270,"IDK") -> 270
B33: Radius (Ohms) | G33: =G18/2 -> 74.55
B34: Start Angle (degrees) | G34: 360
B35: End angle (degrees) | G35: 0
A47: This is for calculating the relay settings | M47: For calculating settings
B48: Generator Data
B49: Voltage (kV, line-to-line) | G49: 20
B50: Power (MVA) | G50: 492
B51: PT Ratio | G51: 167
B52: CT Ratio | G52: 3600
B53: Xd (pu) | G53: 1.1888
B54: X'd (pu) | G54: 0.20577
B55: ZB (ohms secondary) | G55: =(G49^2/G50)*G52/G51 -> 17.525924
...

Sheet Curve
B2: Mho Element - Zone 1 | F2: Mho Element - Zone 2 | L2: Mho Element - Zone 1 | P2: Mho Element - Zone 2
B3: Angle (degrees) | C3: R (ohms) | D3: X (ohms) | F3: Angle (degrees) | G3: R (ohms) | H3: X (ohms) | L3: Angle (degrees) | M3: R (ohms) | N3: X (ohms) | P3: Angle (degrees) | Q3: R (ohms) | R3: X (ohms)
B4: 0 | C4: =Settings!$G$14*COS(RADIANS(B4))/2+Settings!$G$14/2*COS(RADIANS(-90)) -> 57.35 | D4: =Settings!G$14*SIN(RADIANS(B4))/2+Settings!G$14/2*SIN(RADIANS(-90))+Settings!G$15 -> -69.95 | F4: 0 | G4: =Settings!$G$18*COS(RADIANS(F4))/2+Settings!$G$18/2*COS(RADIANS(-90)) -> 74.55 | H4: =Settings!$G$18*SIN(RADIANS(F4))/2+Settings!G$18/2*SIN(RADIANS(-90))+Settings!G$19 -> -87.15 | L4: 0 | M4: =Settings!$G$61*COS(RADIANS(L4))/2+Settings!$G$61/2*COS(RADIANS(-90)) -> 8.7629619 | N4: =Settings!$G$61*SIN(RADIANS(L4))/2+Settings!$G$61/2*SIN(RADIANS(-90))+Settings!G$62 -> -10.566117 | P4: 0 | Q4: =Settings!$G$65*COS(RADIANS(P4))/2+Settings!$G$65/2*COS(RADIANS(-90)) -> 10.417409 | R4: =Settings!$G$65*SIN(RADIANS(P4))/2+Settings!$G$65/2*SIN(RADIANS(-90))+Settings!G$66 -> -12.220564
B5: =B4+10 -> 10 | C5: =Settings!G$14*COS(RADIANS(B5))/2+Settings!G$14/2*COS(RADIANS(-90)) -> 56.478725 | D5: =Settings!G$14*SIN(RADIANS(B5))/2+Settings!G$14/2*SIN(RADIANS(-90))+Settings!G$15 -> -59.991277 | F5: =F4+10 -> 10 | G5: =Settings!$G$18*COS(RADIANS(F5))/2+Settings!$G$18/2*COS(RADIANS(-90)) -> 73.417418 | H5: =Settings!$G$18*SIN(RADIANS(F5))/2+Settings!G$18/2*SIN(RADIANS(-90))+Settings!G$19 -> -74.204528 | L5: =L4+10 -> 10 | M5: =Settings!$G$61*COS(RADIANS(L5))/2+Settings!$G$61/2*COS(RADIANS(-90)) -> 8.6298328 | N5: =Settings!$G$61*SIN(RADIANS(L5))/2+Settings!$G$61/2*SIN(RADIANS(-90))+Settings!G$62 -> -9.0444442 | P5: =P4+10 -> 10 | Q5: =Settings!$G$65*COS(RADIANS(P5))/2+Settings!$G$65/2*COS(RADIANS(-90)) -> 10.259145 | R5: =Settings!$G$65*SIN(RADIANS(P5))/2+Settings!$G$65/2*SIN(RADIANS(-90))+Settings!G$66 -> -10.4116
B6: =B5+10 -> 20 | C6: =Settings!G$14*COS(RADIANS(B6))/2+Settings!G$14/2*COS(RADIANS(-90)) -> 53.891372 | D6: =Settings!G$14*SIN(RADIANS(B6))/2+Settings!G$14/2*SIN(RADIANS(-90))+Settings!G$15 -> -50.335145 | F6: =F5+10 -> 20 | G6: =Settings!$G$18*COS(RADIANS(F6))/2+Settings!$G$18/2*COS(RADIANS(-90)) -> 70.054085 | H6: =Settings!$G$18*SIN(RADIANS(F6))/2+Settings!G$18/2*SIN(RADIANS(-90))+Settings!G$19 -> -61.652398 | L6: =L5+10 -> 20 | M6: =Settings!$G$61*COS(RADIANS(L6))/2+Settings!$G$61/2*COS(RADIANS(-90)) -> 8.2344906 | N6: =Settings!$G$61*SIN(RADIANS(L6))/2+Settings!$G$61/2*SIN(RADIANS(-90))+Settings!G$62 -> -7.5690071 | P6: =P5+10 -> 20 | Q6: =Settings!$G$65*COS(RADIANS(P6))/2+Settings!$G$65/2*COS(RADIANS(-90)) -> 9.7891624 | R6: =Settings!$G$65*SIN(RADIANS(P6))/2+Settings!$G$65/2*SIN(RADIANS(-90))+Settings!G$66 -> -8.6576
B7: =B6+10 -> 30 | C7: =Settings!G$14*COS(RADIANS(B7))/2+Settings!G$14/2*COS(RADIANS(-90)) -> 49.666557 | D7: =Settings!G$14*SIN(RADIANS(B7))/2+Settings!G$14/2*SIN(RADIANS(-90))+Settings!G$15 -> -41.275 | F7: =F6+10 -> 30 | G7: =Settings!$G$18*COS(RADIANS(F7))/2+Settings!$G$18/2*COS(RADIANS(-90)) -> 64.562194 | H7: =Settings!$G$18*SIN(RADIANS(F7))/2+Settings!G$18/2*SIN(RADIANS(-90))+Settings!G$19 -> -49.875 | L7: =L6+10 -> 30 | M7: =Settings!$G$61*COS(RADIANS(L7))/2+Settings!$G$61/2*COS(RADIANS(-90)) -> 7.5889476 | N7: =Settings!$G$61*SIN(RADIANS(L7))/2+Settings!$G$61/2*SIN(RADIANS(-90))+Settings!G$62 -> -6.1846356 | P7: =P6+10 -> 30 | Q7: =Settings!$G$65*COS(RADIANS(P7))/2+Settings!$G$65/2*COS(RADIANS(-90)) -> 9.0217409 | R7: =Settings!$G$65*SIN(RADIANS(P7))/2+Settings!$G$65/2*SIN(RADIANS(-90))+Settings!G$66 -> -7.0118592
B8: =B7+10 -> 40 | C8: =Settings!G$14*COS(RADIANS(B8))/2+Settings!G$14/2*COS(RADIANS(-90)) -> 43.932649 | D8: =Settings!G$14*SIN(RADIANS(B8))/2+Settings!G$14/2*SIN(RADIANS(-90))+Settings!G$15 -> -33.086131 | F8: =F7+10 -> 40 | G8: =Settings!$G$18*COS(RADIANS(F8))/2+Settings!$G$18/2*COS(RADIANS(-90)) -> 57.108613 | H8: =Settings!$G$18*SIN(RADIANS(F8))/2+Settings!G$18/2*SIN(RADIANS(-90))+Settings!G$19 -> -39.230184 | L8: =L7+10 -> 40 | M8: =Settings!$G$61*COS(RADIANS(L8))/2+Settings!$G$61/2*COS(RADIANS(-90)) -> 6.7128183 | N8: =Settings!$G$61*SIN(RADIANS(L8))/2+Settings!$G$61/2*SIN(RADIANS(-90))+Settings!G$62 -> -4.9333932 | P8: =P7+10 -> 40 | Q8: =Settings!$G$65*COS(RADIANS(P8))/2+Settings!$G$65/2*COS(RADIANS(-90)) -> 7.9801983 | R8: =Settings!$G$65*SIN(RADIANS(P8))/2+Settings!$G$65/2*SIN(RADIANS(-90))+Settings!G$66 -> -5.5243823
B9: =B8+10 -> 50 | C9: =Settings!G$14*COS(RADIANS(B9))/2+Settings!G$14/2*COS(RADIANS(-90)) -> 36.863869 | D9: =Settings!G$14*SIN(RADIANS(B9))/2+Settings!G$14/2*SIN(RADIANS(-90))+Settings!G$15 -> -26.017351 | F9: =F8+10 -> 50 | G9: =Settings!$G$18*COS(RADIANS(F9))/2+Settings!$G$18/2*COS(RADIANS(-90)) -> 47.919816 | H9: =Settings!$G$18*SIN(RADIANS(F9))/2+Settings!G$18/2*SIN(RADIANS(-90))+Settings!G$19 -> -30.041387 | L9: =L8+10 -> 50 | M9: =Settings!$G$61*COS(RADIANS(L9))/2+Settings!$G$61/2*COS(RADIANS(-90)) -> 5.6327233 | N9: =Settings!$G$61*SIN(RADIANS(L9))/2+Settings!$G$61/2*SIN(RADIANS(-90))+Settings!G$62 -> -3.8532983 | P9: =P8+10 -> 50 | Q9: =Settings!$G$65*COS(RADIANS(P9))/2+Settings!$G$65/2*COS(RADIANS(-90)) -> 6.6961815 | R9: =Settings!$G$65*SIN(RADIANS(P9))/2+Settings!$G$65/2*SIN(RADIANS(-90))+Settings!G$66 -> -4.2403654
B10: =B9+10 -> 60 | C10: =Settings!G$14*COS(RADIANS(B10))/2+Settings!G$14/2*COS(RADIANS(-90)) -> 28.675 | D10: =Settings!G$14*SIN(RADIANS(B10))/2+Settings!G$14/2*SIN(RADIANS(-90))+Settings!G$15 -> -20.283443 | F10: =F9+10 -> 60 | G10: =Settings!$G$18*COS(RADIANS(F10))/2+Settings!$G$18/2*COS(RADIANS(-90)) -> 37.275 | H10: =Settings!$G$18*SIN(RADIANS(F10))/2+Settings!G$18/2*SIN(RADIANS(-90))+Settings!G$19 -> -22.587806 | L10: =L9+10 -> 60 | M10: =Settings!$G$61*COS(RADIANS(L10))/2+Settings!$G$61/2*COS(RADIANS(-90)) -> 4.3814809 | N10: =Settings!$G$61*SIN(RADIANS(L10))/2+Settings!$G$61/2*SIN(RADIANS(-90))+Settings!G$62 -> -2.9771689 | P10: =P9+10 -> 60 | Q10: =Settings!$G$65*COS(RADIANS(P10))/2+Settings!$G$65/2*COS(RADIANS(-90)) -> 5.2087045 | R10: =Settings!$G$65*SIN(RADIANS(P10))/2+Settings!$G$65/2*SIN(RADIANS(-90))+Settings!G$66 -> -3.1988228
B11: =B10+10 -> 70 | C11: =Settings!G$14*COS(RADIANS(B11))/2+Settings!G$14/2*COS(RADIANS(-90)) -> 19.614855 | D11: =Settings!G$14*SIN(RADIANS(B11))/2+Settings!G$14/2*SIN(RADIANS(-90))+Settings!G$15 -> -16.058628 | F11: =F10+10 -> 70 | G11: =Settings!$G$18*COS(RADIANS(F11))/2+Settings!$G$18/2*COS(RADIANS(-90)) -> 25.497602 | H11: =Settings!$G$18*SIN(RADIANS(F11))/2+Settings!G$18/2*SIN(RADIANS(-90))+Settings!G$19 -> -17.095915 | L11: =L10+10 -> 70 | M11: =Settings!$G$61*COS(RADIANS(L11))/2+Settings!$G$61/2*COS(RADIANS(-90)) -> 2.9971095 | N11: =Settings!$G$61*SIN(RADIANS(L11))/2+Settings!$G$61/2*SIN(RADIANS(-90))+Settings!G$62 -> -2.3316259 | P11: =P10+10 -> 70 | Q11: =Settings!$G$65*COS(RADIANS(P11))/2+Settings!$G$65/2*COS(RADIANS(-90)) -> 3.5629637 | R11: =Settings!$G$65*SIN(RADIANS(P11))/2+Settings!$G$65/2*SIN(RADIANS(-90))+Settings!G$66 -> -2.4314013
B12: =B11+10 -> 80 | C12: =Settings!G$14*COS(RADIANS(B12))/2+Settings!G$14/2*COS(RADIANS(-90)) -> 9.958723 | D12: =Settings!G$14*SIN(RADIANS(B12))/2+Settings!G$14/2*SIN(RADIANS(-90))+Settings!G$15 -> -13.471275 | F12: =F11+10 -> 80 | G12: =Settings!$G$18*COS(RADIANS(F12))/2+Settings!$G$18/2*COS(RADIANS(-90)) -> 12.945472 | H12: =Settings!$G$18*SIN(RADIANS(F12))/2+Settings!G$18/2*SIN(RADIANS(-90))+Settings!G$19 -> -13.732582 | L12: =L11+10 -> 80 | M12: =Settings!$G$61*COS(RADIANS(L12))/2+Settings!$G$61/2*COS(RADIANS(-90)) -> 1.5216724 | N12: =Settings!$G$61*SIN(RADIANS(L12))/2+Settings!$G$61/2*SIN(RADIANS(-90))+Settings!G$62 -> -1.9362837 | P12: =P11+10 -> 80 | Q12: =Settings!$G$65*COS(RADIANS(P12))/2+Settings!$G$65/2*COS(RADIANS(-90)) -> 1.8089641 | R12: =Settings!$G$65*SIN(RADIANS(P12))/2+Settings!$G$65/2*SIN(RADIANS(-90))+Settings!G$66 -> -1.9614185
B13: =B12+10 -> 90 | C13: =Settings!G$14*COS(RADIANS(B13))/2+Settings!G$14/2*COS(RADIANS(-90)) -> 7.0262264e-15 | D13: =Settings!G$14*SIN(RADIANS(B13))/2+Settings!G$14/2*SIN(RADIANS(-90))+Settings!G$15 -> -12.6 | F13: =F12+10 -> 90 | G13: =Settings!$G$18*COS(RADIANS(F13))/2+Settings!$G$18/2*COS(RADIANS(-90)) -> 9.1334817e-15 | H13: =Settings!$G$18*SIN(RADIANS(F13))/2+Settings!G$18/2*SIN(RADIANS(-90))+Settings!G$19 -> -12.6 | L13: =L12+10 -> 90 | M13: =Settings!$G$61*COS(RADIANS(L13))/2+Settings!$G$61/2*COS(RADIANS(-90)) -> 1.0735929e-15 | N13: =Settings!$G$61*SIN(RADIANS(L13))/2+Settings!$G$61/2*SIN(RADIANS(-90))+Settings!G$62 -> -1.8031547 | P13: =P12+10 -> 90 | Q13: =Settings!$G$65*COS(RADIANS(P13))/2+Settings!$G$65/2*COS(RADIANS(-90)) -> 1.2762873e-15 | R13: =Settings!$G$65*SIN(RADIANS(P13))/2+Settings!$G$65/2*SIN(RADIANS(-90))+Settings!G$66 -> -1.8031547
B14: =B13+10 -> 100 | C14: =Settings!G$14*COS(RADIANS(B14))/2+Settings!G$14/2*COS(RADIANS(-90)) -> -9.958723 | D14: =Settings!G$14*SIN(RADIANS(B14))/2+Settings!G$14/2*SIN(RADIANS(-90))+Settings!G$15 -> -13.471275 | F14: =F13+10 -> 100 | G14: =Settings!$G$18*COS(RADIANS(F14))/2+Settings!$G$18/2*COS(RADIANS(-90)) -> -12.945472 | H14: =Settings!$G$18*SIN(RADIANS(F14))/2+Settings!G$18/2*SIN(RADIANS(-90))+Settings!G$19 -> -13.732582 | L14: =L13+10 -> 100 | M14: =Settings!$G$61*COS(RADIANS(L14))/2+Settings!$G$61/2*COS(RADIANS(-90)) -> -1.5216724 | N14: =Settings!$G$61*SIN(RADIANS(L14))/2+Settings!$G$61/2*SIN(RADIANS(-90))+Settings!G$62 -> -1.9362837 | P14: =P13+10 -> 100 | Q14: =Settings!$G$65*COS(RADIANS(P14))/2+Settings!$G$65/2*COS(RADIANS(-90)) -> -1.8089641 | R14: =Settings!$G$65*SIN(RADIANS(P14))/2+Settings!$G$65/2*SIN(RADIANS(-90))+Settings!G$66 -> -1.9614185
B15: =B14+10 -> 110 | C15: =Settings!G$14*COS(RADIANS(B15))/2+Settings!G$14/2*COS(RADIANS(-90)) -> -19.614855 | D15: =Settings!G$14*SIN(RADIANS(B15))/2+Settings!G$14/2*SIN(RADIANS(-90))+Settings!G$15 -> -16.058628 | F15: =F14+10 -> 110 | G15: =Settings!$G$18*COS(RADIANS(F15))/2+Settings!$G$18/2*COS(RADIANS(-90)) -> -25.497602 | H15: =Settings!$G$18*SIN(RADIANS(F15))/2+Settings!G$18/2*SIN(RADIANS(-90))+Settings!G$19 -> -17.095915 | L15: =L14+10 -> 110 | M15: =Settings!$G$61*COS(RADIANS(L15))/2+Settings!$G$61/2*COS(RADIANS(-90)) -> -2.9971095 | N15: =Settings!$G$61*SIN(RADIANS(L15))/2+Settings!$G$61/2*SIN(RADIANS(-90))+Settings!G$62 -> -2.3316259 | P15: =P14+10 -> 110 | Q15: =Settings!$G$65*COS(RADIANS(P15))/2+Settings!$G$65/2*COS(RADIANS(-90)) -> -3.5629637 | R15: =Settings!$G$65*SIN(RADIANS(P15))/2+Settings!$G$65/2*SIN(RADIANS(-90))+Settings!G$66 -> -2.4314013
B16: =B15+10 -> 120 | C16: =Settings!G$14*COS(RADIANS(B16))/2+Settings!G$14/2*COS(RADIANS(-90)) -> -28.675 | D16: =Settings!G$14*SIN(RADIANS(B16))/2+Settings!G$14/2*SIN(RADIANS(-90))+Settings!G$15 -> -20.283443 | F16: =F15+10 -> 120 | G16: =Settings!$G$18*COS(RADIANS(F16))/2+Settings!$G$18/2*COS(RADIANS(-90)) -> -37.275 | H16: =Settings!$G$18*SIN(RADIANS(F16))/2+Settings!G$18/2*SIN(RADIANS(-90))+Settings!G$19 -> -22.587806 | L16: =L15+10 -> 120 | M16: =Settings!$G$61*COS(RADIANS(L16))/2+Settings!$G$61/2*COS(RADIANS(-90)) -> -4.3814809 | N16: =Settings!$G$61*SIN(RADIANS(L16))/2+Settings!$G$61/2*SIN(RADIANS(-90))+Settings!G$62 -> -2.9771689 | P16: =P15+10 -> 120 | Q16: =Settings!$G$65*COS(RADIANS(P16))/2+Settings!$G$65/2*COS(RADIANS(-90)) -> -5.2087045 | R16: =Settings!$G$65*SIN(RADIANS(P16))/2+Settings!$G$65/2*SIN(RADIANS(-90))+Settings!G$66 -> -3.1988228
... B40: =B39+10 -> 360 | C40: =Settings!G$14*COS(RADIANS(B40))/2+Settings!G$14/2*COS(RADIANS(-90)) -> 57.35 | D40: =Settings!G$14*SIN(RADIANS(B40))/2+Settings!G$14/2*SIN(RADIANS(-90))+Settings!G$15 -> -69.95 | F40: =F39+10 -> 360 | G40: =Settings!$G$18*COS(RADIANS(F40))/2+Settings!$G$18/2*COS(RADIANS(-90)) -> 74.55 | H40: =Settings!$G$18*SIN(RADIANS(F40))/2+Settings!G$18/2*SIN(RADIANS(-90))+Settings!G$19 -> -87.15 | L40: =L39+10 -> 360 | M40: =Settings!$G$61*COS(RADIANS(L40))/2+Settings!$G$61/2*COS(RADIANS(-90)) -> 8.7629619 | N40: =Settings!$G$61*SIN(RADIANS(L40))/2+Settings!$G$61/2*SIN(RADIANS(-90))+Settings!G$62 -> -10.566117 | P40: =P39+10 -> 360 | Q40: =Settings!$G$65*COS(RADIANS(P40))/2+Settings!$G$65/2*COS(RADIANS(-90)) -> 10.417409 | R40: =Settings!$G$65*SIN(RADIANS(P40))/2+Settings!$G$65/2*SIN(RADIANS(-90))+Settings!G$66 -> -12.220564
